Traceback (most recent call last):
  File "/Users/jordivilla/miniconda3/lib/python3.11/site-packages/jupyter_cache/executors/utils.py", line 58, in single_nb_execution
    executenb(
  File "/Users/jordivilla/miniconda3/lib/python3.11/site-packages/nbclient/client.py", line 1305, in execute
    return NotebookClient(nb=nb, resources=resources, km=km, **kwargs).execute()
           ^^^^^^^^^^^^^^^^^^^^^^^^^^^^^^^^^^^^^^^^^^^^^^^^^^^^^^^^^^^^^^^^^^^^^
  File "/Users/jordivilla/miniconda3/lib/python3.11/site-packages/jupyter_core/utils/__init__.py", line 166, in wrapped
    return loop.run_until_complete(inner)
           ^^^^^^^^^^^^^^^^^^^^^^^^^^^^^^
  File "/Users/jordivilla/miniconda3/lib/python3.11/asyncio/base_events.py", line 653, in run_until_complete
    return future.result()
           ^^^^^^^^^^^^^^^
  File "/Users/jordivilla/miniconda3/lib/python3.11/site-packages/nbclient/client.py", line 705, in async_execute
    await self.async_execute_cell(
  File "/Users/jordivilla/miniconda3/lib/python3.11/site-packages/nbclient/client.py", line 1058, in async_execute_cell
    await self._check_raise_for_error(cell, cell_index, exec_reply)
  File "/Users/jordivilla/miniconda3/lib/python3.11/site-packages/nbclient/client.py", line 914, in _check_raise_for_error
    raise CellExecutionError.from_cell_and_msg(cell, exec_reply_content)
nbclient.exceptions.CellExecutionError: An error occurred while executing the following cell:
------------------
#!pip install pandas
import pandas as pd
from pathlib import Path

# define the directory where I keep the data
datadir = Path("""~/data""")
filename=datadir/"gnomAD_v2.1.1_ENSG00000176153_2022_03_22_11_24_32.csv"
filename=datadir/"gnomAD_v2.1.1_ENSG00000233276_2022_03_22_10_54_50.csv"


# load the CSV file
data=pd.read_csv(filename)
# print(data)
data.loc[:,["Protein Consequence","ClinVar Clinical Significance"]]
data = data[data["Protein Consequence"].notna()].loc[:,["Protein Consequence","ClinVar Clinical Significance"]]
data[data["ClinVar Clinical Significance"].notna()]

#contain_values = df[df[
------------------


[0;31m---------------------------------------------------------------------------[0m
[0;31mModuleNotFoundError[0m                       Traceback (most recent call last)
Cell [0;32mIn[1], line 2[0m
[1;32m      1[0m [38;5;66;03m#!pip install pandas[39;00m
[0;32m----> 2[0m [38;5;28;01mimport[39;00m [38;5;21;01mpandas[39;00m [38;5;28;01mas[39;00m [38;5;21;01mpd[39;00m
[1;32m      3[0m [38;5;28;01mfrom[39;00m [38;5;21;01mpathlib[39;00m [38;5;28;01mimport[39;00m Path
[1;32m      5[0m [38;5;66;03m# define the directory where I keep the data[39;00m

[0;31mModuleNotFoundError[0m: No module named 'pandas'

